Workbook
Name NativeTimeline_Date: #N/A
Name Slicer_Day_Name1: #N/A
Name Slicer_Day_Type1: #N/A
Name Slicer_Is_Holiday1: #N/A
Name Slicer_Temperature1: #N/A
Name Slicer_Weather_Description: #N/A

Sheet Readme
C2: BIKE SHARING DEMAND ANALYSIS
C5: Dataset Description
C6: This project analyzes hourly bike rental data from 1 January to 14 February 2011, covering rental demand along with weather, time, holiday, and user-type information.
C9: Purpose
C10: To understand patterns in bike rental demand and how rentals vary across time, weather conditions, holidays, and user types.
C13: WORKBOOK GUIDE
C15: Sheet | E15: Purpose
C16: Clean_Dataset1/2/3 | E16: Prepared datasets used in the analysis
C17: Cleaned_DatasetA/B | E17: Combined datasets used for analysis
C18: Lookup_Tables | E18: Reference tables used for data classification
C19: Calculations | E19: Key statistics, KPIs, correlations, and data checks
C20: Pivot_Analysis | E20: Analysis of rental demand across time, weather, day type, and user type
C21: Charts and Analysis | E21: Visual summary of key patterns and findings
C22: Forecast | E22: Rental demand forecast
C23: Anomaly | E23: Analysis of unusual daily rental patterns
C24: Dashboard | E24: Summary of key KPIs, charts, and findings

Sheet Clean_Dataset1
A1: instant | B1: dteday | C1: season | D1: yr | E1: mnth | F1: hr | G1: holiday | H1: weekday | I1: weathersit | J1: temp
A2: 1 | B2: 40544 | C2: 1 | D2: 0 | E2: 1 | F2: 0 | G2: FALSE | H2: 6 | I2: 1 | J2: 0.24
A3: 2 | B3: 40544 | C3: 1 | D3: 0 | E3: 1 | F3: 1 | G3: FALSE | H3: 6 | I3: 1 | J3: 0.22
A4: 3 | B4: 40544 | C4: 1 | D4: 0 | E4: 1 | F4: 2 | G4: FALSE | H4: 6 | I4: 1 | J4: 0.22
A5: 4 | B5: 40544 | C5: 1 | D5: 0 | E5: 1 | F5: 3 | G5: FALSE | H5: 6 | I5: 1 | J5: 0.24
A6: 5 | B6: 40544 | C6: 1 | D6: 0 | E6: 1 | F6: 4 | G6: FALSE | H6: 6 | I6: 1 | J6: 0.24
A7: 6 | B7: 40544 | C7: 1 | D7: 0 | E7: 1 | F7: 5 | G7: FALSE | H7: 6 | I7: 2 | J7: 0.24
A8: 7 | B8: 40544 | C8: 1 | D8: 0 | E8: 1 | F8: 6 | G8: FALSE | H8: 6 | I8: 1 | J8: 0.22
A9: 8 | B9: 40544 | C9: 1 | D9: 0 | E9: 1 | F9: 7 | G9: FALSE | H9: 6 | I9: 1 | J9: 0.2
A10: 9 | B10: 40544 | C10: 1 | D10: 0 | E10: 1 | F10: 8 | G10: FALSE | H10: 6 | I10: 1 | J10: 0.24
A11: 10 | B11: 40544 | C11: 1 | D11: 0 | E11: 1 | F11: 9 | G11: FALSE | H11: 6 | I11: 1 | J11: 0.32
A12: 11 | B12: 40544 | C12: 1 | D12: 0 | E12: 1 | F12: 10 | G12: FALSE | H12: 6 | I12: 1 | J12: 0.38
A13: 12 | B13: 40544 | C13: 1 | D13: 0 | E13: 1 | F13: 11 | G13: FALSE | H13: 6 | I13: 1 | J13: 0.36
... A611: 610 | B611: 40571 | C611: 1 | D611: 0 | E611: 1 | F611: 15 | G611: FALSE | H611: 5 | I611: 2 | J611: 0.2

Sheet Cleaned_Dataset2
A1: instant | B1: atemp | C1: hum | D1: windspeed | E1: casual | F1: registered | G1: cnt
A2: 1 | B2: 0.2879 | C2: 0.81 | D2: 0 | E2: 3 | F2: 13 | G2: 16
A3: 2 | B3: 0.2727 | C3: 0.8 | D3: 0 | E3: 8 | F3: 32 | G3: 40
A4: 3 | B4: 0.2727 | C4: 0.8 | D4: 0 | E4: 5 | F4: 27 | G4: 32
A5: 4 | B5: 0.2879 | C5: 0.75 | D5: 0 | E5: 3 | F5: 10 | G5: 13
A6: 5 | B6: 0.2879 | C6: 0.75 | D6: 0 | E6: 0 | F6: 1 | G6: 1
A7: 6 | B7: 0.2576 | C7: 0.75 | D7: 0.0896 | E7: 0 | F7: 1 | G7: 1
A8: 7 | B8: 0.2727 | C8: 0.8 | D8: 0 | E8: 2 | F8: 0 | G8: 2
A9: 8 | B9: 0.2576 | C9: 0.86 | D9: 0 | E9: 1 | F9: 2 | G9: 3
A10: 9 | B10: 0.19993489 | C10: 0.75 | D10: 0 | E10: 1 | F10: 7 | G10: 8
A11: 10 | B11: 0.3485 | C11: 0.76 | D11: 0 | E11: 8 | F11: 6 | G11: 14
A12: 11 | B12: 0.3939 | C12: 0.76 | D12: 0.2537 | E12: 12 | F12: 24 | G12: 36
A13: 12 | B13: 0.3333 | C13: 0.81 | D13: 0.2836 | E13: 26 | F13: 30 | G13: 56
... A611: 610 | B611: 0.2576 | C611: 0.86 | D611: 0 | E611: 1 | F611: 40 | G611: 41

Sheet Cleaned_Dataset3
A1: Record_ID | B1: Date | C1: Season_Code | D1: Year | E1: Month | F1: Hour | G1: Is_Holiday | H1: Day_Code | I1: Weather_Code | J1: Temperature | K1: Assumed_Temperature | L1: Humidity | M1: Wind_Speed | N1: Casual_Rentals | O1: Registered_Rentals | P1: Total_Rentals
A2: 611 | B2: 40571 | C2: 1 | D2: 0 | E2: 1 | F2: 16 | G2: FALSE | H2: 5 | I2: 1 | J2: 0.22 | K2: 0.2727 | L2: 0.8 | M2: 0 | N2: 10 | O2: 70 | P2: 80
A3: 612 | B3: 40571 | C3: 1 | D3: 0 | E3: 1 | F3: 17 | G3: FALSE | H3: 5 | I3: 1 | J3: 0.24 | K3: 0.2424 | L3: 0.75 | M3: 0.1343 | N3: 2 | O3: 147 | P3: 149
A4: 613 | B4: 40571 | C4: 1 | D4: 0 | E4: 1 | F4: 18 | G4: FALSE | H4: 5 | I4: 1 | J4: 0.24 | K4: 0.2273 | L4: 0.75 | M4: 0.194 | N4: 2 | O4: 107 | P4: 109
A5: 614 | B5: 40571 | C5: 1 | D5: 0 | E5: 1 | F5: 19 | G5: FALSE | H5: 5 | I5: 2 | J5: 0.24 | K5: 0.2424 | L5: 0.75 | M5: 0.1343 | N5: 5 | O5: 84 | P5: 89
A6: 615 | B6: 40571 | C6: 1 | D6: 0 | E6: 1 | F6: 20 | G6: FALSE | H6: 5 | I6: 2 | J6: 0.24 | K6: 0.2273 | L6: 0.7 | M6: 0.194 | N6: 1 | O6: 61 | P6: 62
A7: 616 | B7: 40571 | C7: 1 | D7: 0 | E7: 1 | F7: 21 | G7: FALSE | H7: 5 | I7: 2 | J7: 0.22 | K7: 0.2273 | L7: 0.75 | M7: 0.1343 | N7: 1 | O7: 57 | P7: 58
A8: 617 | B8: 40571 | C8: 1 | D8: 0 | E8: 1 | F8: 22 | G8: FALSE | H8: 5 | I8: 1 | J8: 0.24 | K8: 0.2121 | L8: 0.65 | M8: 0.3582 | N8: 0 | O8: 26 | P8: 26
A9: 618 | B9: 40571 | C9: 1 | D9: 0 | E9: 1 | F9: 23 | G9: FALSE | H9: 5 | I9: 1 | J9: 0.24 | K9: 0.2273 | L9: 0.6 | M9: 0.2239 | N9: 1 | O9: 22 | P9: 23
A10: 619 | B10: 40572 | C10: 1 | D10: 0 | E10: 1 | F10: 0 | G10: FALSE | H10: 6 | I10: 1 | J10: 0.22 | K10: 0.197 | L10: 0.64 | M10: 0.3582 | N10: 2 | O10: 26 | P10: 28
A11: 620 | B11: 40572 | C11: 1 | D11: 0 | E11: 1 | F11: 1 | G11: FALSE | H11: 6 | I11: 1 | J11: 0.22 | K11: 0.2273 | L11: 0.64 | M11: 0.194 | N11: 0 | O11: 20 | P11: 20
A12: 621 | B12: 40572 | C12: 1 | D12: 0 | E12: 1 | F12: 2 | G12: FALSE | H12: 6 | I12: 1 | J12: 0.22 | K12: 0.2273 | L12: 0.64 | M12: 0.1642 | N12: 0 | O12: 15 | P12: 15
A13: 622 | B13: 40572 | C13: 1 | D13: 0 | E13: 1 | F13: 3 | G13: FALSE | H13: 6 | I13: 1 | J13: 0.2 | K13: 0.2121 | L13: 0.64 | M13: 0.1343 | N13: 3 | O13: 5 | P13: 8
... A391: 1000 | B391: 40588 | C391: 1 | D391: 0 | E391: 2 | F391: 7 | G391: FALSE | H391: 1 | I391: 1 | J391: 0.34 | K391: 0.303 | L391: 0.46 | M391: 0.2985 | N391: 2 | O391: 96 | P391: 98

Sheet Cleaned_DatasetA
A1: Record_ID | B1: Date | C1: Season_Code | D1: Year | E1: Month | F1: Hour | G1: Is_Holiday | H1: Day_Code | I1: Weather_Code | J1: Temperature | K1: Assumed_Temperature | L1: Humidity | M1: Wind_Speed | N1: Casual_Rentals | O1: Registered_Rentals | P1: Total_Rentals
A2: 1 | B2: 40544 | C2: 1 | D2: 0 | E2: 1 | F2: 0 | G2: FALSE | H2: 6 | I2: 1 | J2: 0.24 | K2: 0.2879 | L2: 0.81 | M2: 0 | N2: 3 | O2: 13 | P2: 16
A3: 2 | B3: 40544 | C3: 1 | D3: 0 | E3: 1 | F3: 1 | G3: FALSE | H3: 6 | I3: 1 | J3: 0.22 | K3: 0.2727 | L3: 0.8 | M3: 0 | N3: 8 | O3: 32 | P3: 40
A4: 3 | B4: 40544 | C4: 1 | D4: 0 | E4: 1 | F4: 2 | G4: FALSE | H4: 6 | I4: 1 | J4: 0.22 | K4: 0.2727 | L4: 0.8 | M4: 0 | N4: 5 | O4: 27 | P4: 32
A5: 4 | B5: 40544 | C5: 1 | D5: 0 | E5: 1 | F5: 3 | G5: FALSE | H5: 6 | I5: 1 | J5: 0.24 | K5: 0.2879 | L5: 0.75 | M5: 0 | N5: 3 | O5: 10 | P5: 13
A6: 5 | B6: 40544 | C6: 1 | D6: 0 | E6: 1 | F6: 4 | G6: FALSE | H6: 6 | I6: 1 | J6: 0.24 | K6: 0.2879 | L6: 0.75 | M6: 0 | N6: 0 | O6: 1 | P6: 1
A7: 6 | B7: 40544 | C7: 1 | D7: 0 | E7: 1 | F7: 5 | G7: FALSE | H7: 6 | I7: 2 | J7: 0.24 | K7: 0.2576 | L7: 0.75 | M7: 0.0896 | N7: 0 | O7: 1 | P7: 1
A8: 7 | B8: 40544 | C8: 1 | D8: 0 | E8: 1 | F8: 6 | G8: FALSE | H8: 6 | I8: 1 | J8: 0.22 | K8: 0.2727 | L8: 0.8 | M8: 0 | N8: 2 | O8: 0 | P8: 2
A9: 8 | B9: 40544 | C9: 1 | D9: 0 | E9: 1 | F9: 7 | G9: FALSE | H9: 6 | I9: 1 | J9: 0.2 | K9: 0.2576 | L9: 0.86 | M9: 0 | N9: 1 | O9: 2 | P9: 3
A10: 9 | B10: 40544 | C10: 1 | D10: 0 | E10: 1 | F10: 8 | G10: FALSE | H10: 6 | I10: 1 | J10: 0.24 | K10: 0.19993489 | L10: 0.75 | M10: 0 | N10: 1 | O10: 7 | P10: 8
A11: 10 | B11: 40544 | C11: 1 | D11: 0 | E11: 1 | F11: 9 | G11: FALSE | H11: 6 | I11: 1 | J11: 0.32 | K11: 0.3485 | L11: 0.76 | M11: 0 | N11: 8 | O11: 6 | P11: 14
A12: 11 | B12: 40544 | C12: 1 | D12: 0 | E12: 1 | F12: 10 | G12: FALSE | H12: 6 | I12: 1 | J12: 0.38 | K12: 0.3939 | L12: 0.76 | M12: 0.2537 | N12: 12 | O12: 24 | P12: 36
A13: 12 | B13: 40544 | C13: 1 | D13: 0 | E13: 1 | F13: 11 | G13: FALSE | H13: 6 | I13: 1 | J13: 0.36 | K13: 0.3333 | L13: 0.81 | M13: 0.2836 | N13: 26 | O13: 30 | P13: 56
... A611: 610 | B611: 40571 | C611: 1 | D611: 0 | E611: 1 | F611: 15 | G611: FALSE | H611: 5 | I611: 2 | J611: 0.2 | K611: 0.2576 | L611: 0.86 | M611: 0 | N611: 1 | O611: 40 | P611: 41

Sheet Cleaned_DatasetB
A1: Record_ID | B1: Date | C1: Season_Code | D1: Year | E1: Month | F1: Hour | G1: Is_Holiday | H1: Day_Code | I1: Day_Type | J1: Weather_Code | K1: Temperature | L1: Assumed_Temperature | M1: Humidity | N1: Wind_Speed | O1: Casual_Rentals | P1: Registered_Rentals | Q1: Total_Rentals | R1: Weather_Description | S1: Day_Name | T1: Month_Name | U1: Working_Day
A2: 1 | B2: 40544 | C2: 1 | D2: 0 | E2: 1 | F2: 0 | G2: FALSE | H2: 6 | I2: =IF(OR(Cleaned_datasetB[[#This Row],[Day_Code]]=0,Cleaned_datasetB[[#This Row],[Day_Code]]=6),"Weekend","Weekday") -> Weekend | J2: 1 | K2: 0.24 | L2: 0.2879 | M2: 0.81 | N2: 0 | O2: 3 | P2: 13 | Q2: 16 | R2: =VLOOKUP(Cleaned_datasetB[[#This Row],[Weather_Code]],Lookup_Tables!$E$9:$F$13,2,FALSE) -> Clear | S2: =INDEX(Lookup_Tables!$I$10:$I$16,MATCH(Cleaned_datasetB[[#This Row],[Day_Code]],Lookup_Tables!$H$10:$H$16,0)) -> Saturday | T2: =VLOOKUP(Cleaned_datasetB[[#This Row],[Month]], Lookup_Tables!$K$8:$L$19, 2, FALSE) -> January | U2: =IF(AND(Cleaned_datasetB[[#This Row],[Day_Type]]="Weekday",Cleaned_datasetB[[#This Row],[Is_Holiday]]=FALSE),"Working Day","Non-Working Day") -> Non-Working Day
A3: 2 | B3: 40544 | C3: 1 | D3: 0 | E3: 1 | F3: 1 | G3: FALSE | H3: 6 | I3: =IF(OR(Cleaned_datasetB[[#This Row],[Day_Code]]=0,Cleaned_datasetB[[#This Row],[Day_Code]]=6),"Weekend","Weekday") -> Weekend | J3: 1 | K3: 0.22 | L3: 0.2727 | M3: 0.8 | N3: 0 | O3: 8 | P3: 32 | Q3: 40 | R3: =VLOOKUP(Cleaned_datasetB[[#This Row],[Weather_Code]],Lookup_Tables!$E$9:$F$13,2,FALSE) -> Clear | S3: =INDEX(Lookup_Tables!$I$10:$I$16,MATCH(Cleaned_datasetB[[#This Row],[Day_Code]],Lookup_Tables!$H$10:$H$16,0)) -> Saturday | T3: =VLOOKUP(Cleaned_datasetB[[#This Row],[Month]], Lookup_Tables!$K$8:$L$19, 2, FALSE) -> January | U3: =IF(AND(Cleaned_datasetB[[#This Row],[Day_Type]]="Weekday",Cleaned_datasetB[[#This Row],[Is_Holiday]]=FALSE),"Working Day","Non-Working Day") -> Non-Working Day
A4: 3 | B4: 40544 | C4: 1 | D4: 0 | E4: 1 | F4: 2 | G4: FALSE | H4: 6 | I4: =IF(OR(Cleaned_datasetB[[#This Row],[Day_Code]]=0,Cleaned_datasetB[[#This Row],[Day_Code]]=6),"Weekend","Weekday") -> Weekend | J4: 1 | K4: 0.22 | L4: 0.2727 | M4: 0.8 | N4: 0 | O4: 5 | P4: 27 | Q4: 32 | R4: =VLOOKUP(Cleaned_datasetB[[#This Row],[Weather_Code]],Lookup_Tables!$E$9:$F$13,2,FALSE) -> Clear | S4: =INDEX(Lookup_Tables!$I$10:$I$16,MATCH(Cleaned_datasetB[[#This Row],[Day_Code]],Lookup_Tables!$H$10:$H$16,0)) -> Saturday | T4: =VLOOKUP(Cleaned_datasetB[[#This Row],[Month]], Lookup_Tables!$K$8:$L$19, 2, FALSE) -> January | U4: =IF(AND(Cleaned_datasetB[[#This Row],[Day_Type]]="Weekday",Cleaned_datasetB[[#This Row],[Is_Holiday]]=FALSE),"Working Day","Non-Working Day") -> Non-Working Day
A5: 4 | B5: 40544 | C5: 1 | D5: 0 | E5: 1 | F5: 3 | G5: FALSE | H5: 6 | I5: =IF(OR(Cleaned_datasetB[[#This Row],[Day_Code]]=0,Cleaned_datasetB[[#This Row],[Day_Code]]=6),"Weekend","Weekday") -> Weekend | J5: 1 | K5: 0.24 | L5: 0.2879 | M5: 0.75 | N5: 0 | O5: 3 | P5: 10 | Q5: 13 | R5: =VLOOKUP(Cleaned_datasetB[[#This Row],[Weather_Code]],Lookup_Tables!$E$9:$F$13,2,FALSE) -> Clear | S5: =INDEX(Lookup_Tables!$I$10:$I$16,MATCH(Cleaned_datasetB[[#This Row],[Day_Code]],Lookup_Tables!$H$10:$H$16,0)) -> Saturday | T5: =VLOOKUP(Cleaned_datasetB[[#This Row],[Month]], Lookup_Tables!$K$8:$L$19, 2, FALSE) -> January | U5: =IF(AND(Cleaned_datasetB[[#This Row],[Day_Type]]="Weekday",Cleaned_datasetB[[#This Row],[Is_Holiday]]=FALSE),"Working Day","Non-Working Day") -> Non-Working Day
A6: 5 | B6: 40544 | C6: 1 | D6: 0 | E6: 1 | F6: 4 | G6: FALSE | H6: 6 | I6: =IF(OR(Cleaned_datasetB[[#This Row],[Day_Code]]=0,Cleaned_datasetB[[#This Row],[Day_Code]]=6),"Weekend","Weekday") -> Weekend | J6: 1 | K6: 0.24 | L6: 0.2879 | M6: 0.75 | N6: 0 | O6: 0 | P6: 1 | Q6: 1 | R6: =VLOOKUP(Cleaned_datasetB[[#This Row],[Weather_Code]],Lookup_Tables!$E$9:$F$13,2,FALSE) -> Clear | S6: =INDEX(Lookup_Tables!$I$10:$I$16,MATCH(Cleaned_datasetB[[#This Row],[Day_Code]],Lookup_Tables!$H$10:$H$16,0)) -> Saturday | T6: =VLOOKUP(Cleaned_datasetB[[#This Row],[Month]], Lookup_Tables!$K$8:$L$19, 2, FALSE) -> January | U6: =IF(AND(Cleaned_datasetB[[#This Row],[Day_Type]]="Weekday",Cleaned_datasetB[[#This Row],[Is_Holiday]]=FALSE),"Working Day","Non-Working Day") -> Non-Working Day | W6: Hours with zero rentals aren't recorded as rows — confirmed count is never 0 across all 1,000 records.
A7: 6 | B7: 40544 | C7: 1 | D7: 0 | E7: 1 | F7: 5 | G7: FALSE | H7: 6 | I7: =IF(OR(Cleaned_datasetB[[#This Row],[Day_Code]]=0,Cleaned_datasetB[[#This Row],[Day_Code]]=6),"Weekend","Weekday") -> Weekend | J7: 2 | K7: 0.24 | L7: 0.2576 | M7: 0.75 | N7: 0.0896 | O7: 0 | P7: 1 | Q7: 1 | R7: =VLOOKUP(Cleaned_datasetB[[#This Row],[Weather_Code]],Lookup_Tables!$E$9:$F$13,2,FALSE) -> Cloudy | S7: =INDEX(Lookup_Tables!$I$10:$I$16,MATCH(Cleaned_datasetB[[#This Row],[Day_Code]],Lookup_Tables!$H$10:$H$16,0)) -> Saturday | T7: =VLOOKUP(Cleaned_datasetB[[#This Row],[Month]], Lookup_Tables!$K$8:$L$19, 2, FALSE) -> January | U7: =IF(AND(Cleaned_datasetB[[#This Row],[Day_Type]]="Weekday",Cleaned_datasetB[[#This Row],[Is_Holiday]]=FALSE),"Working Day","Non-Working Day") -> Non-Working Day
A8: 7 | B8: 40544 | C8: 1 | D8: 0 | E8: 1 | F8: 6 | G8: FALSE | H8: 6 | I8: =IF(OR(Cleaned_datasetB[[#This Row],[Day_Code]]=0,Cleaned_datasetB[[#This Row],[Day_Code]]=6),"Weekend","Weekday") -> Weekend | J8: 1 | K8: 0.22 | L8: 0.2727 | M8: 0.8 | N8: 0 | O8: 2 | P8: 0 | Q8: 2 | R8: =VLOOKUP(Cleaned_datasetB[[#This Row],[Weather_Code]],Lookup_Tables!$E$9:$F$13,2,FALSE) -> Clear | S8: =INDEX(Lookup_Tables!$I$10:$I$16,MATCH(Cleaned_datasetB[[#This Row],[Day_Code]],Lookup_Tables!$H$10:$H$16,0)) -> Saturday | T8: =VLOOKUP(Cleaned_datasetB[[#This Row],[Month]], Lookup_Tables!$K$8:$L$19, 2, FALSE) -> January | U8: =IF(AND(Cleaned_datasetB[[#This Row],[Day_Type]]="Weekday",Cleaned_datasetB[[#This Row],[Is_Holiday]]=FALSE),"Working Day","Non-Working Day") -> Non-Working Day
A9: 8 | B9: 40544 | C9: 1 | D9: 0 | E9: 1 | F9: 7 | G9: FALSE | H9: 6 | I9: =IF(OR(Cleaned_datasetB[[#This Row],[Day_Code]]=0,Cleaned_datasetB[[#This Row],[Day_Code]]=6),"Weekend","Weekday") -> Weekend | J9: 1 | K9: 0.2 | L9: 0.2576 | M9: 0.86 | N9: 0 | O9: 1 | P9: 2 | Q9: 3 | R9: =VLOOKUP(Cleaned_datasetB[[#This Row],[Weather_Code]],Lookup_Tables!$E$9:$F$13,2,FALSE) -> Clear | S9: =INDEX(Lookup_Tables!$I$10:$I$16,MATCH(Cleaned_datasetB[[#This Row],[Day_Code]],Lookup_Tables!$H$10:$H$16,0)) -> Saturday | T9: =VLOOKUP(Cleaned_datasetB[[#This Row],[Month]], Lookup_Tables!$K$8:$L$19, 2, FALSE) -> January | U9: =IF(AND(Cleaned_datasetB[[#This Row],[Day_Type]]="Weekday",Cleaned_datasetB[[#This Row],[Is_Holiday]]=FALSE),"Working Day","Non-Working Day") -> Non-Working Day
A10: 9 | B10: 40544 | C10: 1 | D10: 0 | E10: 1 | F10: 8 | G10: FALSE | H10: 6 | I10: =IF(OR(Cleaned_datasetB[[#This Row],[Day_Code]]=0,Cleaned_datasetB[[#This Row],[Day_Code]]=6),"Weekend","Weekday") -> Weekend | J10: 1 | K10: 0.24 | L10: 0.19993489 | M10: 0.75 | N10: 0 | O10: 1 | P10: 7 | Q10: 8 | R10: =VLOOKUP(Cleaned_datasetB[[#This Row],[Weather_Code]],Lookup_Tables!$E$9:$F$13,2,FALSE) -> Clear | S10: =INDEX(Lookup_Tables!$I$10:$I$16,MATCH(Cleaned_datasetB[[#This Row],[Day_Code]],Lookup_Tables!$H$10:$H$16,0)) -> Saturday | T10: =VLOOKUP(Cleaned_datasetB[[#This Row],[Month]], Lookup_Tables!$K$8:$L$19, 2, FALSE) -> January | U10: =IF(AND(Cleaned_datasetB[[#This Row],[Day_Type]]="Weekday",Cleaned_datasetB[[#This Row],[Is_Holiday]]=FALSE),"Working Day","Non-Working Day") -> Non-Working Day
A11: 10 | B11: 40544 | C11: 1 | D11: 0 | E11: 1 | F11: 9 | G11: FALSE | H11: 6 | I11: =IF(OR(Cleaned_datasetB[[#This Row],[Day_Code]]=0,Cleaned_datasetB[[#This Row],[Day_Code]]=6),"Weekend","Weekday") -> Weekend | J11: 1 | K11: 0.32 | L11: 0.3485 | M11: 0.76 | N11: 0 | O11: 8 | P11: 6 | Q11: 14 | R11: =VLOOKUP(Cleaned_datasetB[[#This Row],[Weather_Code]],Lookup_Tables!$E$9:$F$13,2,FALSE) -> Clear | S11: =INDEX(Lookup_Tables!$I$10:$I$16,MATCH(Cleaned_datasetB[[#This Row],[Day_Code]],Lookup_Tables!$H$10:$H$16,0)) -> Saturday | T11: =VLOOKUP(Cleaned_datasetB[[#This Row],[Month]], Lookup_Tables!$K$8:$L$19, 2, FALSE) -> January | U11: =IF(AND(Cleaned_datasetB[[#This Row],[Day_Type]]="Weekday",Cleaned_datasetB[[#This Row],[Is_Holiday]]=FALSE),"Working Day","Non-Working Day") -> Non-Working Day
A12: 11 | B12: 40544 | C12: 1 | D12: 0 | E12: 1 | F12: 10 | G12: FALSE | H12: 6 | I12: =IF(OR(Cleaned_datasetB[[#This Row],[Day_Code]]=0,Cleaned_datasetB[[#This Row],[Day_Code]]=6),"Weekend","Weekday") -> Weekend | J12: 1 | K12: 0.38 | L12: 0.3939 | M12: 0.76 | N12: 0.2537 | O12: 12 | P12: 24 | Q12: 36 | R12: =VLOOKUP(Cleaned_datasetB[[#This Row],[Weather_Code]],Lookup_Tables!$E$9:$F$13,2,FALSE) -> Clear | S12: =INDEX(Lookup_Tables!$I$10:$I$16,MATCH(Cleaned_datasetB[[#This Row],[Day_Code]],Lookup_Tables!$H$10:$H$16,0)) -> Saturday | T12: =VLOOKUP(Cleaned_datasetB[[#This Row],[Month]], Lookup_Tables!$K$8:$L$19, 2, FALSE) -> January | U12: =IF(AND(Cleaned_datasetB[[#This Row],[Day_Type]]="Weekday",Cleaned_datasetB[[#This Row],[Is_Holiday]]=FALSE),"Working Day","Non-Working Day") -> Non-Working Day
A13: 12 | B13: 40544 | C13: 1 | D13: 0 | E13: 1 | F13: 11 | G13: FALSE | H13: 6 | I13: =IF(OR(Cleaned_datasetB[[#This Row],[Day_Code]]=0,Cleaned_datasetB[[#This Row],[Day_Code]]=6),"Weekend","Weekday") -> Weekend | J13: 1 | K13: 0.36 | L13: 0.3333 | M13: 0.81 | N13: 0.2836 | O13: 26 | P13: 30 | Q13: 56 | R13: =VLOOKUP(Cleaned_datasetB[[#This Row],[Weather_Code]],Lookup_Tables!$E$9:$F$13,2,FALSE) -> Clear | S13: =INDEX(Lookup_Tables!$I$10:$I$16,MATCH(Cleaned_datasetB[[#This Row],[Day_Code]],Lookup_Tables!$H$10:$H$16,0)) -> Saturday | T13: =VLOOKUP(Cleaned_datasetB[[#This Row],[Month]], Lookup_Tables!$K$8:$L$19, 2, FALSE) -> January | U13: =IF(AND(Cleaned_datasetB[[#This Row],[Day_Type]]="Weekday",Cleaned_datasetB[[#This Row],[Is_Holiday]]=FALSE),"Working Day","Non-Working Day") -> Non-Working Day
A14: 13 | B14: 40544 | C14: 1 | D14: 0 | E14: 1 | F14: 12 | G14: FALSE | H14: 6 | I14: =IF(OR(Cleaned_datasetB[[#This Row],[Day_Code]]=0,Cleaned_datasetB[[#This Row],[Day_Code]]=6),"Weekend","Weekday") -> Weekend | J14: 1 | K14: 0.42 | L14: 0.4242 | M14: 0.77 | N14: 0.2836 | O14: 29 | P14: 55 | Q14: 84 | R14: =VLOOKUP(Cleaned_datasetB[[#This Row],[Weather_Code]],Lookup_Tables!$E$9:$F$13,2,FALSE) -> Clear | S14: =INDEX(Lookup_Tables!$I$10:$I$16,MATCH(Cleaned_datasetB[[#This Row],[Day_Code]],Lookup_Tables!$H$10:$H$16,0)) -> Saturday | T14: =VLOOKUP(Cleaned_datasetB[[#This Row],[Month]], Lookup_Tables!$K$8:$L$19, 2, FALSE) -> January | U14: =IF(AND(Cleaned_datasetB[[#This Row],[Day_Type]]="Weekday",Cleaned_datasetB[[#This Row],[Is_Holiday]]=FALSE),"Working Day","Non-Working Day") -> Non-Working Day
A15: 14 | B15: 40544 | C15: 1 | D15: 0 | E15: 1 | F15: 13 | G15: FALSE | H15: 6 | I15: =IF(OR(Cleaned_datasetB[[#This Row],[Day_Code]]=0,Cleaned_datasetB[[#This Row],[Day_Code]]=6),"Weekend","Weekday") -> Weekend | J15: 2 | K15: 0.46 | L15: 0.4545 | M15: 0.72 | N15: 0.2985 | O15: 47 | P15: 47 | Q15: 94 | R15: =VLOOKUP(Cleaned_datasetB[[#This Row],[Weather_Code]],Lookup_Tables!$E$9:$F$13,2,FALSE) -> Cloudy | S15: =INDEX(Lookup_Tables!$I$10:$I$16,MATCH(Cleaned_datasetB[[#This Row],[Day_Code]],Lookup_Tables!$H$10:$H$16,0)) -> Saturday | T15: =VLOOKUP(Cleaned_datasetB[[#This Row],[Month]], Lookup_Tables!$K$8:$L$19, 2, FALSE) -> January | U15: =IF(AND(Cleaned_datasetB[[#This Row],[Day_Type]]="Weekday",Cleaned_datasetB[[#This Row],[Is_Holiday]]=FALSE),"Working Day","Non-Working Day") -> Non-Working Day
A16: 15 | B16: 40544 | C16: 1 | D16: 0 | E16: 1 | F16: 14 | G16: FALSE | H16: 6 | I16: =IF(OR(Cleaned_datasetB[[#This Row],[Day_Code]]=0,Cleaned_datasetB[[#This Row],[Day_Code]]=6),"Weekend","Weekday") -> Weekend | J16: 2 | K16: 0.46 | L16: 0.4545 | M16: 0.72 | N16: 0.2836 | O16: 35 | P16: 71 | Q16: 106 | R16: =VLOOKUP(Cleaned_datasetB[[#This Row],[Weather_Code]],Lookup_Tables!$E$9:$F$13,2,FALSE) -> Cloudy | S16: =INDEX(Lookup_Tables!$I$10:$I$16,MATCH(Cleaned_datasetB[[#This Row],[Day_Code]],Lookup_Tables!$H$10:$H$16,0)) -> Saturday | T16: =VLOOKUP(Cleaned_datasetB[[#This Row],[Month]], Lookup_Tables!$K$8:$L$19, 2, FALSE) -> January | U16: =IF(AND(Cleaned_datasetB[[#This Row],[Day_Type]]="Weekday",Cleaned_datasetB[[#This Row],[Is_Holiday]]=FALSE),"Working Day","Non-Working Day") -> Non-Working Day
A17: 16 | B17: 40544 | C17: 1 | D17: 0 | E17: 1 | F17: 15 | G17: FALSE | H17: 6 | I17: =IF(OR(Cleaned_datasetB[[#This Row],[Day_Code]]=0,Cleaned_datasetB[[#This Row],[Day_Code]]=6),"Weekend","Weekday") -> Weekend | J17: 2 | K17: 0.44 | L17: 0.4394 | M17: 0.77 | N17: 0.2985 | O17: 40 | P17: 70 | Q17: 110 | R17: =VLOOKUP(Cleaned_datasetB[[#This Row],[Weather_Code]],Lookup_Tables!$E$9:$F$13,2,FALSE) -> Cloudy | S17: =INDEX(Lookup_Tables!$I$10:$I$16,MATCH(Cleaned_datasetB[[#This Row],[Day_Code]],Lookup_Tables!$H$10:$H$16,0)) -> Saturday | T17: =VLOOKUP(Cleaned_datasetB[[#This Row],[Month]], Lookup_Tables!$K$8:$L$19, 2, FALSE) -> January | U17: =IF(AND(Cleaned_datasetB[[#This Row],[Day_Type]]="Weekday",Cleaned_datasetB[[#This Row],[Is_Holiday]]=FALSE),"Working Day","Non-Working Day") -> Non-Working Day
A18: 17 | B18: 40544 | C18: 1 | D18: 0 | E18: 1 | F18: 16 | G18: FALSE | H18: 6 | I18: =IF(OR(Cleaned_datasetB[[#This Row],[Day_Code]]=0,Cleaned_datasetB[[#This Row],[Day_Code]]=6),"Weekend","Weekday") -> Weekend | J18: 2 | K18: 0.42 | L18: 0.4242 | M18: 0.82 | N18: 0.2985 | O18: 41 | P18: 52 | Q18: 93 | R18: =VLOOKUP(Cleaned_datasetB[[#This Row],[Weather_Code]],Lookup_Tables!$E$9:$F$13,2,FALSE) -> Cloudy | S18: =INDEX(Lookup_Tables!$I$10:$I$16,MATCH(Cleaned_datasetB[[#This Row],[Day_Code]],Lookup_Tables!$H$10:$H$16,0)) -> Saturday | T18: =VLOOKUP(Cleaned_datasetB[[#This Row],[Month]], Lookup_Tables!$K$8:$L$19, 2, FALSE) -> January | U18: =IF(AND(Cleaned_datasetB[[#This Row],[Day_Type]]="Weekday",Cleaned_datasetB[[#This Row],[Is_Holiday]]=FALSE),"Working Day","Non-Working Day") -> Non-Working Day
... A1001: 1000 | B1001: 40588 | C1001: 1 | D1001: 0 | E1001: 2 | F1001: 7 | G1001: FALSE | H1001: 1 | I1001: =IF(OR(Cleaned_datasetB[[#This Row],[Day_Code]]=0,Cleaned_datasetB[[#This Row],[Day_Code]]=6),"Weekend","Weekday") -> Weekday | J1001: 1 | K1001: 0.34 | L1001: 0.303 | M1001: 0.46 | N1001: 0.2985 | O1001: 2 | P1001: 96 | Q1001: 98 | R1001: =VLOOKUP(Cleaned_datasetB[[#This Row],[Weather_Code]],Lookup_Tables!$E$9:$F$13,2,FALSE) -> Clear | S1001: =INDEX(Lookup_Tables!$I$10:$I$16,MATCH(Cleaned_datasetB[[#This Row],[Day_Code]],Lookup_Tables!$H$10:$H$16,0)) -> Monday | T1001: =VLOOKUP(Cleaned_datasetB[[#This Row],[Month]], Lookup_Tables!$K$8:$L$19, 2, FALSE) -> February | U1001: =IF(AND(Cleaned_datasetB[[#This Row],[Day_Type]]="Weekday",Cleaned_datasetB[[#This Row],[Is_Holiday]]=FALSE),"Working Day","Non-Working Day") -> Working Day

Sheet Lookup_Tables
C2: Lookup_Tables
B7: Season_Lookup | E7: Weather_Lookup | H7: Weekday_Lookup | K7: Month_Lookup
B9: Season_Code | C9: Season | E9: Weather_Code | F9: Weather | H9: Day_Code | I9: Day | K9: Month_Code | L9: Month
B10: 1 | C10: Winter | E10: 1 | F10: Clear | H10: 0 | I10: Sunday | K10: 1 | L10: January
B11: 2 | C11: Spring | E11: 2 | F11: Cloudy | H11: 1 | I11: Monday | K11: 2 | L11: February
B12: 3 | C12: Summer | E12: 3 | F12: Light Rain | H12: 2 | I12: Tuesday | K12: 3 | L12: March
B13: 4 | C13: Fall | E13: 4 | F13: Heavy Rain | H13: 3 | I13: Wednesday | K13: 4 | L13: April
H14: 4 | I14: Thursday | K14: 5 | L14: May
H15: 5 | I15: Friday | K15: 6 | L15: June
H16: 6 | I16: Saturday | K16: 7 | L16: July
K17: 8 | L17: August
K18: 9 | L18: September
K19: 10 | L19: October
K20: 11 | L20: November
K21: 12 | L21: December
D24: These are static reference tables used to translate coded values (weather condition, day of week) in the main dataset B

Sheet Calculations
B2: BIKE SHARING DEMAND ANALYSIS — Statistical Summary & Data Insights
Z3: 0 | AA3: =AVERAGEIF(Cleaned_datasetB[Hour], Z3, Cleaned_datasetB[Total_Rentals]) -> 16.348837
Z4: 1 | AA4: =AVERAGEIF(Cleaned_datasetB[Hour], Z4, Cleaned_datasetB[Total_Rentals]) -> 10.697674
Z5: 2 | AA5: =AVERAGEIF(Cleaned_datasetB[Hour], Z5, Cleaned_datasetB[Total_Rentals]) -> 7.1707317
B6: SECTION A — RENTAL DEMAND OVERVIEW | E6: Section B — Descriptive Statistics | K6: Section C — Weather–Demand Relationships | Z6: 3 | AA6: =AVERAGEIF(Cleaned_datasetB[Hour], Z6, Cleaned_datasetB[Total_Rentals]) -> 4.8709677
Z7: 4 | AA7: =AVERAGEIF(Cleaned_datasetB[Hour], Z7, Cleaned_datasetB[Total_Rentals]) -> 2.15625
B8: Measure | C8: Formula | E8: Variable | F8: Average | G8: Minimum | H8: Maximum | I8: Sample Std Dev | K8: Weather Variable | L8: Registered Rentals | M8: Casual Rentals | N8: Total Rentals | Z8: 5 | AA8: =AVERAGEIF(Cleaned_datasetB[Hour], Z8, Cleaned_datasetB[Total_Rentals]) -> 4.2051282
B9: Total Rentals | C9: =SUM(Cleaned_datasetB[Total_Rentals]) -> 58304 | E9: Total Rentals | F9: =AVERAGE(Cleaned_datasetB[Total_Rentals]) -> 58.304 | G9: =MIN(Cleaned_datasetB[Total_Rentals]) -> 1 | H9: =MAX(Cleaned_datasetB[Total_Rentals]) -> 249 | I9: =_xlfn.STDEV.S(Cleaned_datasetB[Total_Rentals]) -> 50.985558 | K9: Temperature | L9: =CORREL(Cleaned_datasetB[Temperature],Cleaned_datasetB[Registered_Rentals]) -> 0.16904505 | M9: =CORREL(Cleaned_datasetB[Temperature],Cleaned_datasetB[Casual_Rentals]) -> 0.47022073 | N9: =CORREL(Cleaned_datasetB[Temperature],Cleaned_datasetB[Total_Rentals]) -> 0.22929155 | Z9: 6 | AA9: =AVERAGEIF(Cleaned_datasetB[Hour], Z9, Cleaned_datasetB[Total_Rentals]) -> 19.571429
B10: Total Casual Rentals | C10: =SUM(Cleaned_datasetB[Casual_Rentals]) -> 4921 | E10: Casual Rentals | F10: =AVERAGE(Cleaned_datasetB[Casual_Rentals]) -> 4.921 | G10: =MIN(Cleaned_datasetB[Casual_Rentals]) -> 0 | H10: =MAX(Cleaned_datasetB[Casual_Rentals]) -> 62 | I10: =_xlfn.STDEV.S(Cleaned_datasetB[Casual_Rentals]) -> 7.6438988 | K10: Apparent Temperature | L10: =CORREL(Cleaned_datasetB[Assumed_Temperature], Cleaned_datasetB[Registered_Rentals]) -> 0.1382308 | M10: =CORREL(Cleaned_datasetB[Assumed_Temperature], Cleaned_datasetB[Casual_Rentals]) -> 0.42355275 | N10: =CORREL(Cleaned_datasetB[Assumed_Temperature], Cleaned_datasetB[Total_Rentals]) -> 0.19334918 | Z10: 7 | AA10: =AVERAGEIF(Cleaned_datasetB[Hour], Z10, Cleaned_datasetB[Total_Rentals]) -> 54.395349
B11: Total Registered Rentals | C11: =SUM(Cleaned_datasetB[Registered_Rentals]) -> 53383 | E11: Registered Rentals | F11: =AVERAGE(Cleaned_datasetB[Registered_Rentals]) -> 53.383 | G11: =MIN(Cleaned_datasetB[Registered_Rentals]) -> 0 | H11: =MAX(Cleaned_datasetB[Registered_Rentals]) -> 247 | I11: =_xlfn.STDEV.S(Cleaned_datasetB[Registered_Rentals]) -> 47.893968 | K11: Humidity | L11: =CORREL(Cleaned_datasetB[Humidity],Cleaned_datasetB[Registered_Rentals]) -> -0.22937044 | M11: =CORREL(Cleaned_datasetB[Humidity],Cleaned_datasetB[Casual_Rentals]) -> -0.25940745 | N11: =CORREL(Cleaned_datasetB[Humidity],Cleaned_datasetB[Total_Rentals]) -> -0.2543533 | Z11: 8 | AA11: =AVERAGEIF(Cleaned_datasetB[Hour], Z11, Cleaned_datasetB[Total_Rentals]) -> 128.28571
B12: Average Rentals per Record | C12: =AVERAGE(Cleaned_datasetB[Total_Rentals]) -> 58.304 | E12: Temperature | F12: =AVERAGE(Cleaned_datasetB[Temperature]) -> 0.2059 | G12: =MIN(Cleaned_datasetB[Temperature]) -> 0.02 | H12: =MAX(Cleaned_datasetB[Temperature]) -> 0.46 | I12: =_xlfn.STDEV.S(Cleaned_datasetB[Temperature]) -> 0.078977386 | K12: Wind Speed | L12: =CORREL(Cleaned_datasetB[Wind_Speed],Cleaned_datasetB[Registered_Rentals]) -> 0.090058729 | M12: =CORREL(Cleaned_datasetB[Wind_Speed],Cleaned_datasetB[Casual_Rentals]) -> 0.12939194 | N12: =CORREL(Cleaned_datasetB[Wind_Speed],Cleaned_datasetB[Total_Rentals]) -> 0.10399668 | Z12: 9 | AA12: =AVERAGEIF(Cleaned_datasetB[Hour], Z12, Cleaned_datasetB[Total_Rentals]) -> 87.428571
B13: Maximum Rentals in a Record | C13: =MAX(Cleaned_datasetB[Total_Rentals]) -> 249 | E13: Assumed Temperature | F13: =AVERAGE(Cleaned_datasetB[Assumed_Temperature]) -> 0.21182558 | G13: =MIN(Cleaned_datasetB[Assumed_Temperature]) -> 0 | H13: =MAX(Cleaned_datasetB[Assumed_Temperature]) -> 0.4545 | I13: =_xlfn.STDEV.S(Cleaned_datasetB[Assumed_Temperature]) -> 0.076289755 | Z13: 10 | AA13: =AVERAGEIF(Cleaned_datasetB[Hour], Z13, Cleaned_datasetB[Total_Rentals]) -> 53.642857
B14: Minimum Rentals in a Record | C14: =MIN(Cleaned_datasetB[Total_Rentals]) -> 1 | E14: Humidity | F14: =AVERAGE(Cleaned_datasetB[Humidity]) -> 0.58248 | G14: =MIN(Cleaned_datasetB[Humidity]) -> 0.21 | H14: =MAX(Cleaned_datasetB[Humidity]) -> 1 | I14: =_xlfn.STDEV.S(Cleaned_datasetB[Humidity]) -> 0.18797709 | K14: Registered users appear less affected by weather, while casual demand is more weather-sensitive. | Z14: 11 | AA14: =AVERAGEIF(Cleaned_datasetB[Hour], Z14, Cleaned_datasetB[Total_Rentals]) -> 59.380952
B15: Number of Records | C15: =COUNT(Cleaned_datasetB[Record_ID]) -> 1000 | E15: Wind Speed | F15: =AVERAGE(Cleaned_datasetB[Wind_Speed]) -> 0.1949313 | G15: =MIN(Cleaned_datasetB[Wind_Speed]) -> 0 | H15: =MAX(Cleaned_datasetB[Wind_Speed]) -> 0.5821 | I15: =_xlfn.STDEV.S(Cleaned_datasetB[Wind_Speed]) -> 0.12912607 | Z15: 12 | AA15: =AVERAGEIF(Cleaned_datasetB[Hour], Z15, Cleaned_datasetB[Total_Rentals]) -> 76.348837
B16: Peak Demand Hour | C16: =INDEX(Z3:Z26, MATCH(MAX(AA3:AA26), AA3:AA26, 0)) -> 17 | Z16: 13 | AA16: =AVERAGEIF(Cleaned_datasetB[Hour], Z16, Cleaned_datasetB[Total_Rentals]) -> 78.511628
B17: Casual Rental Share | C17: =SUM(Cleaned_datasetB[Casual_Rentals])/SUM(Cleaned_datasetB[Total_Rentals]) -> 0.084402442 | E17: The average rental demand is 58.30, while the standard deviation is 50.99, showing that the number of rentals can vary significantly from one hour to another. | AA17: 14 | AB17: =AVERAGEIF(Cleaned_datasetB[Hour], AA17, Cleaned_datasetB[Total_Rentals]) -> 74.418605
B18: Registered Rental Share | C18: =SUM(Cleaned_datasetB[Registered_Rentals])/SUM(Cleaned_datasetB[Total_Rentals]) -> 0.91559756 | Z18: 15 | AA18: =AVERAGEIF(Cleaned_datasetB[Hour], Z18, Cleaned_datasetB[Total_Rentals]) -> 77.953488
Z19: 16 | AA19: =AVERAGEIF(Cleaned_datasetB[Hour], Z19, Cleaned_datasetB[Total_Rentals]) -> 89.272727
B20: Registered riders account for 91.6% of all rentals, while casual riders account for only 8.4%. | Z20: 17 | AA20: =AVERAGEIF(Cleaned_datasetB[Hour], Z20, Cleaned_datasetB[Total_Rentals]) -> 140.20455
Z21: 18 | AA21: =AVERAGEIF(Cleaned_datasetB[Hour], Z21, Cleaned_datasetB[Total_Rentals]) -> 122.86047
Z22: 19 | AA22: =AVERAGEIF(Cleaned_datasetB[Hour], Z22, Cleaned_datasetB[Total_Rentals]) -> 85.139535
B23: Section D — Demand by Day Type and Holiday | E23: Section E — Weather Condition Summary | K23: Section F — Text Functions & Data Checks | Z23: 20 | AA23: =AVERAGEIF(Cleaned_datasetB[Hour], Z23, Cleaned_datasetB[Total_Rentals]) -> 61.767442
Z24: 21 | AA24: =AVERAGEIF(Cleaned_datasetB[Hour], Z24, Cleaned_datasetB[Total_Rentals]) -> 46.418605
B25: Measure | C25: Formula | E25: Weather | F25: Count of Records | G25: Total Rentals | H25: Average Rentals per Record | K25: Purpose | L25: Formula | Z25: 22 | AA25: =AVERAGEIF(Cleaned_datasetB[Hour], Z25, Cleaned_datasetB[Total_Rentals]) -> 35.069767
B26: Average Rentals on Holidays | C26: =AVERAGEIF(Cleaned_datasetB[Is_Holiday],TRUE,Cleaned_datasetB[Total_Rentals]) -> 41.666667 | E26: Clear | F26: =COUNTIF(Cleaned_datasetB[Weather_Description],"Clear") -> 606 | G26: =SUMIF(Cleaned_datasetB[Weather_Description],"Clear",Cleaned_datasetB[Total_Rentals]) -> 37373 | H26: =AVERAGEIF(Cleaned_datasetB[Weather_Description],"Clear",Cleaned_datasetB[Total_Rentals]) -> 61.671617 | K26: Extract Day | L26: =LEFT(TEXT('Cleaned_DatasetB'!B2,"DD-MM-YYYY"),2) -> 01 | Z26: 23 | AA26: =AVERAGEIF(Cleaned_datasetB[Hour], Z26, Cleaned_datasetB[Total_Rentals]) -> 25.186047
B27: Average Rentals on Non-Holidays | C27: =AVERAGEIF(Cleaned_datasetB[Is_Holiday],FALSE,Cleaned_datasetB[Total_Rentals]) -> 58.713115 | E27: Cloudy | F27: =COUNTIF(Cleaned_datasetB[Weather_Description],"Cloudy") -> 309 | G27: =SUMIF(Cleaned_datasetB[Weather_Description],"Cloudy",Cleaned_datasetB[Total_Rentals]) -> 18106 | H27: =AVERAGEIF(Cleaned_datasetB[Weather_Description],"Cloudy",Cleaned_datasetB[Total_Rentals]) -> 58.595469 | K27: Extract Year | L27: =RIGHT(TEXT('Cleaned_DatasetB'!B2,"DD-MM-YYYY"),4) -> 2011
B28: Average Rentals on Weekends | C28: =AVERAGEIF(Cleaned_datasetB[Day_Type],"Weekend",Cleaned_datasetB[Total_Rentals]) -> 48.087879 | E28: Light Snow | F28: =COUNTIF(Cleaned_datasetB[Weather_Description],"Light Rain") -> 84 | G28: =SUMIF(Cleaned_datasetB[Weather_Description],"Light Rain",Cleaned_datasetB[Total_Rentals]) -> 2789 | H28: =AVERAGEIF(Cleaned_datasetB[Weather_Description],"Light Rain",Cleaned_datasetB[Total_Rentals]) -> 33.202381 | K28: Report Date Range | L28: =TEXT(MIN(Cleaned_datasetB[Date]),"DD-MMM-YYYY")&" to "&TEXT(MAX(Cleaned_datasetB[Date]),"DD-MMM-YYYY") -> 01-Jan-2011 to 14-Feb-2011
B29: Average Rentals on Weekdays | C29: =AVERAGEIF(Cleaned_datasetB[Day_Type],"Weekday",Cleaned_datasetB[Total_Rentals]) -> 63.335821 | E29: Heavy Rain | F29: =COUNTIF(Cleaned_datasetB[Weather_Description],"Heavy Rain") -> 1 | G29: =SUMIF(Cleaned_datasetB[Weather_Description],"Heavy Rain",Cleaned_datasetB[Total_Rentals]) -> 36 | H29: =AVERAGEIF(Cleaned_datasetB[Weather_Description],"Heavy Rain",Cleaned_datasetB[Total_Rentals]) -> 36 | K29: Report Date Season | L29: =VLOOKUP(INDEX(Cleaned_datasetB[Season_Code],1), Lookup_Tables!$B$10:$C$13, 2, FALSE) -> Winter
B31: The higher weekday demand and lower holiday/weekend demand suggest that rentals are strongly associated with regular weekday travel. | E31: Rental demand is higher under Clear and Cloudy conditions and lower under Light Snow. Heavy Rain has only one record, so no general conclusion can be drawn from it.

Sheet Pivot_Analysis
C1: PIVOT TABLE ANALYSIS — Bike Sharing Demand
D5: TIME ANALYSIS
H7: Rentals by Hour
C8: Rentals by Month | H8: Hours | I8: Average of Casual_Rentals | J8: Average of Registered_Rentals | K8: Average of Total_Rentals
C9: Months | D9: Average of Casual_Rentals | E9: Average of Registered_Rentals | F9: Average of Total_Rentals | H9: 0 | I9: 1.7209302 | J9: 14.627907 | K9: 16.348837
C10: January | D10: 4.4665698 | E10: 51.040698 | F10: 55.507267 | H10: 1 | I10: 1.1162791 | J10: 9.5813953 | K10: 10.697674
C11: February | D11: 5.9230769 | E11: 58.548077 | F11: 64.471154 | H11: 2 | I11: 0.80487805 | J11: 6.3658537 | K11: 7.1707317
C12: Grand Total | D12: 4.921 | E12: 53.383 | F12: 58.304 | H12: 3 | I12: 1.0967742 | J12: 3.7741935 | K12: 4.8709677
H13: 4 | I13: 0.21875 | J13: 1.9375 | K13: 2.15625
H14: 5 | I14: 0.076923077 | J14: 4.1282051 | K14: 4.2051282
C15: Rentals by Weekday | H15: 6 | I15: 0.5 | J15: 19.071429 | K15: 19.571429 | L15: Rental demand shows prominent peaks around the morning and evening commuting hours, particularly around 8 AM and 5 PM.
C16: Days | D16: Average of Casual_Rentals | E16: Average of Registered_Rentals | F16: Average of Total_Rentals | H16: 7 | I16: 1.4883721 | J16: 52.906977 | K16: 54.395349
C17: Sunday | D17: 9.0060976 | E17: 40.512195 | F17: 49.518293 | H17: 8 | I17: 3.0238095 | J17: 125.2619 | K17: 128.28571
C18: Monday | D18: 3.5838926 | E18: 53.127517 | F18: 56.711409 | H18: 9 | I18: 4.0952381 | J18: 83.333333 | K18: 87.428571
C19: Tuesday | D19: 3.5984252 | E19: 62.409449 | F19: 66.007874 | H19: 10 | I19: 5.1428571 | J19: 48.5 | K19: 53.642857
C20: Wednesday | D20: 2.6259542 | E20: 58.816794 | F20: 61.442748 | H20: 11 | I20: 8.7380952 | J20: 50.642857 | K20: 59.380952
C21: Thursday | D21: 2.656 | E21: 65.008 | F21: 67.664 | H21: 12 | I21: 11.209302 | J21: 65.139535 | K21: 76.348837
C22: Friday | D22: 4 | E22: 61.905797 | F22: 65.905797 | H22: 13 | I22: 11.930233 | J22: 66.581395 | K22: 78.511628
C23: Saturday | D23: 7.3795181 | E23: 39.295181 | F23: 46.674699 | H23: 14 | I23: 10.837209 | J23: 63.581395 | K23: 74.418605
C24: Grand Total | D24: 4.921 | E24: 53.383 | F24: 58.304 | H24: 15 | I24: 12.465116 | J24: 65.488372 | K24: 77.953488
H25: 16 | I25: 11.204545 | J25: 78.068182 | K25: 89.272727
C26: Demand is strongest midweek (Tuesday–Thursday), while weekends show significantly lower demand, highlighting the weekday commuter pattern. | H26: 17 | I26: 8.9772727 | J26: 131.22727 | K26: 140.20455
H27: 18 | I27: 5.1627907 | J27: 117.69767 | K27: 122.86047
H28: 19 | I28: 4.3488372 | J28: 80.790698 | K28: 85.139535
H29: 20 | I29: 3.255814 | J29: 58.511628 | K29: 61.767442
H30: 21 | I30: 2.7209302 | J30: 43.697674 | K30: 46.418605
H31: 22 | I31: 2.3953488 | J31: 32.674419 | K31: 35.069767
H32: 23 | I32: 2.3488372 | J32: 22.837209 | K32: 25.186047
H33: Grand Total | I33: 4.921 | J33: 53.383 | K33: 58.304
D35: WEATHER / CONDITIONS ANALYSIS
C38: Rentals by Weather Condition | H38: Rentals by Temperature
C39: Weather | D39: Average of Casual_Rentals | E39: Average of Registered_Rentals | F39: Average of Total_Rentals | H39: Temperature | I39: Average of Casual_Rentals | J39: Average of Registered_Rentals | K39: Average of Total_Rentals
C40: Clear | D40: 5.2986799 | E40: 56.372937 | F40: 61.671617 | H40: 0-0.1 | I40: 1.8627451 | J40: 27.941176 | K40: 29.803922
C41: Cloudy | D41: 4.9773463 | E41: 53.618123 | F41: 58.595469 | H41: 0.1-0.2 | I41: 2.3395722 | J41: 47.783422 | K41: 50.122995
C42: Light Rain | D42: 2.0357143 | E42: 31.166667 | F42: 33.202381 | H42: 0.2-0.3 | I42: 4.5400458 | J42: 55.455378 | K42: 59.995423
C43: Heavy Rain | D43: 1 | E43: 35 | F43: 36 | H43: 0.3-0.4 | I43: 13.971429 | J43: 79.904762 | K43: 93.87619
C44: Grand Total | D44: 4.921 | E44: 53.383 | F44: 58.304 | H44: 0.4-0.5 | I44: 15.151515 | J44: 44.333333 | K44: 59.484848
H45: Grand Total | I45: 4.921 | J45: 53.383 | K45: 58.304
H49: Rentals by Humidity | L49: Strongest single-variable pattern: rentals nearly halve from low to high humidity
H50: Humidity | I50: Average of Casual_Rentals | J50: Average of Registered_Rentals | K50: Average of Total_Rentals
...

Sheet Charts and Analysis
E2: Bike Sharing Demand Analysis
F6: SECTION A — TIME ANALYSIS
F8: Avg Rentals by Hour | N8: Weekday vs Weekend by Hour
F27: Avg Rentals by Day of Week | N27: Working Day vs Non-Working
D44: Working days average ~64 rentals vs ~48 on non-working days — the clearest evidence of commuter-driven demand.
F47: SECTION B — WEATHER & ENVIRONMENTAL
F49: Avg Rentals by Weather | N49: Avg Rentals by Humidity
E68: Temperature vs Total Rentals | M68: Rentals by Weather Severity
Z71: Weather Condition | AA71: Total Rentals
Z72: Clear | AA72: =Pivot_Analysis!F40 -> 61.671617
Z73: Cloudy | AA73: =Pivot_Analysis!F41 -> 58.595469
Z74: Light Rain | AA74: =Pivot_Analysis!F43 -> 36
Z75: Heavy Rain | AA75: =Pivot_Analysis!F42 -> 33.202381
F86: SECTION C — RIDER TYPE ANALYSIS
E88: Casual vs Registered Rentals by Hour
D105: Registered riders show a sharp commute double-peak; casual riders peak once, midday — different systems.
D108: KEY OBSERVATIONS
D109: # Demand is commuter-driven: weekday demand (~63/record) outpaces weekends (~48/record), and demand peaks sharply at 8 AM and 5 PM.
D111: #Registered riders dominate the system (91.6% of all rentals) and ride consistently regardless of weather; casual riders (8.4%) are far more weather-sensitive, especially to temperature.
D114: # Humidity is the strongest single environmental driver — average demand nearly halves from low- to high-humidity hours.
D116: # Demand declines steadily as weather worsens, from Clear through Light Rain (Heavy Rain excluded — only 1 record, not statistically reliable).
D118: #Working days show meaningfully higher demand than non-working days, the clearest confirmation of the commuter-driven pattern.

Sheet Forecast
B2: FORECAST — BIKE SHARING DEMAND
B6: A. Historical Daily Summary | G6: B. FORECAST | M6: C. Forecast Chart
B8: Date | C8: Casual Rentals | D8: Registered Rentals | E8: Total Rentals | G8: Date | H8: Historical Trend | I8: Forecast | J8: Lower Bound | K8: Upper Bound
B9: {=_xlfn._xlws.SORT(_xlfn.UNIQUE(Cleaned_datasetB[Date]))} -> 40544 | C9: =SUMIFS(Cleaned_datasetB[Casual_Rentals],Cleaned_datasetB[Date],B9) -> 331 | D9: =SUMIFS(Cleaned_datasetB[Registered_Rentals],Cleaned_datasetB[Date],B9) -> 654 | E9: =C9+D9 -> 985 | G9: 40544 | H9: 978.6085
B10: 40545 | C10: =SUMIFS(Cleaned_datasetB[Casual_Rentals],Cleaned_datasetB[Date],B10) -> 131 | D10: =SUMIFS(Cleaned_datasetB[Registered_Rentals],Cleaned_datasetB[Date],B10) -> 670 | E10: =C10+D10 -> 801 | G10: 40545 | H10: 1027.8907
B11: 40546 | C11: =SUMIFS(Cleaned_datasetB[Casual_Rentals],Cleaned_datasetB[Date],B11) -> 120 | D11: =SUMIFS(Cleaned_datasetB[Registered_Rentals],Cleaned_datasetB[Date],B11) -> 1229 | E11: =C11+D11 -> 1349 | G11: 40546 | H11: 1232.4162
B12: 40547 | C12: =SUMIFS(Cleaned_datasetB[Casual_Rentals],Cleaned_datasetB[Date],B12) -> 108 | D12: =SUMIFS(Cleaned_datasetB[Registered_Rentals],Cleaned_datasetB[Date],B12) -> 1454 | E12: =C12+D12 -> 1562 | G12: 40547 | H12: 1208.5644
B13: 40548 | C13: =SUMIFS(Cleaned_datasetB[Casual_Rentals],Cleaned_datasetB[Date],B13) -> 82 | D13: =SUMIFS(Cleaned_datasetB[Registered_Rentals],Cleaned_datasetB[Date],B13) -> 1518 | E13: =C13+D13 -> 1600 | G13: 40548 | H13: 1303.4948
B14: 40549 | C14: =SUMIFS(Cleaned_datasetB[Casual_Rentals],Cleaned_datasetB[Date],B14) -> 88 | D14: =SUMIFS(Cleaned_datasetB[Registered_Rentals],Cleaned_datasetB[Date],B14) -> 1518 | E14: =C14+D14 -> 1606 | G14: 40549 | H14: 1411.2005
B15: 40550 | C15: =SUMIFS(Cleaned_datasetB[Casual_Rentals],Cleaned_datasetB[Date],B15) -> 148 | D15: =SUMIFS(Cleaned_datasetB[Registered_Rentals],Cleaned_datasetB[Date],B15) -> 1362 | E15: =C15+D15 -> 1510 | G15: 40550 | H15: 1415.8183
B16: 40551 | C16: =SUMIFS(Cleaned_datasetB[Casual_Rentals],Cleaned_datasetB[Date],B16) -> 68 | D16: =SUMIFS(Cleaned_datasetB[Registered_Rentals],Cleaned_datasetB[Date],B16) -> 891 | E16: =C16+D16 -> 959 | G16: 40551 | H16: 1021.3959
B17: 40552 | C17: =SUMIFS(Cleaned_datasetB[Casual_Rentals],Cleaned_datasetB[Date],B17) -> 54 | D17: =SUMIFS(Cleaned_datasetB[Registered_Rentals],Cleaned_datasetB[Date],B17) -> 768 | E17: =C17+D17 -> 822 | G17: 40552 | H17: 1070.678
B18: 40553 | C18: =SUMIFS(Cleaned_datasetB[Casual_Rentals],Cleaned_datasetB[Date],B18) -> 41 | D18: =SUMIFS(Cleaned_datasetB[Registered_Rentals],Cleaned_datasetB[Date],B18) -> 1280 | E18: =C18+D18 -> 1321 | G18: 40553 | H18: 1275.2036
B19: 40554 | C19: =SUMIFS(Cleaned_datasetB[Casual_Rentals],Cleaned_datasetB[Date],B19) -> 43 | D19: =SUMIFS(Cleaned_datasetB[Registered_Rentals],Cleaned_datasetB[Date],B19) -> 1220 | E19: =C19+D19 -> 1263 | G19: 40554 | H19: 1251.3518
B20: 40555 | C20: =SUMIFS(Cleaned_datasetB[Casual_Rentals],Cleaned_datasetB[Date],B20) -> 25 | D20: =SUMIFS(Cleaned_datasetB[Registered_Rentals],Cleaned_datasetB[Date],B20) -> 1137 | E20: =C20+D20 -> 1162 | G20: 40555 | H20: 1346.2822
B21: 40556 | C21: =SUMIFS(Cleaned_datasetB[Casual_Rentals],Cleaned_datasetB[Date],B21) -> 38 | D21: =SUMIFS(Cleaned_datasetB[Registered_Rentals],Cleaned_datasetB[Date],B21) -> 1368 | E21: =C21+D21 -> 1406 | G21: 40556 | H21: 1453.9879
... B29: 40564 | C29: =SUMIFS(Cleaned_datasetB[Casual_Rentals],Cleaned_datasetB[Date],B29) -> 75 | D29: =SUMIFS(Cleaned_datasetB[Registered_Rentals],Cleaned_datasetB[Date],B29) -> 1468 | E29: =C29+D29 -> 1543 | G29: 40564 | H29: 1501.3931
B30: 40565 | C30: =SUMIFS(Cleaned_datasetB[Casual_Rentals],Cleaned_datasetB[Date],B30) -> 93 | D30: =SUMIFS(Cleaned_datasetB[Registered_Rentals],Cleaned_datasetB[Date],B30) -> 888 | E30: =C30+D30 -> 981 | G30: 40565 | H30: 1106.9707 | M30: D. FORECAST SUMMARY
B31: 40566 | C31: =SUMIFS(Cleaned_datasetB[Casual_Rentals],Cleaned_datasetB[Date],B31) -> 150 | D31: =SUMIFS(Cleaned_datasetB[Registered_Rentals],Cleaned_datasetB[Date],B31) -> 836 | E31: =C31+D31 -> 986 | G31: 40566 | H31: 1156.2528
B32: 40567 | C32: =SUMIFS(Cleaned_datasetB[Casual_Rentals],Cleaned_datasetB[Date],B32) -> 86 | D32: =SUMIFS(Cleaned_datasetB[Registered_Rentals],Cleaned_datasetB[Date],B32) -> 1330 | E32: =C32+D32 -> 1416 | G32: 40567 | H32: 1360.7783 | N32: Forecast Summary | O32: Value
B33: 40568 | C33: =SUMIFS(Cleaned_datasetB[Casual_Rentals],Cleaned_datasetB[Date],B33) -> 186 | D33: =SUMIFS(Cleaned_datasetB[Registered_Rentals],Cleaned_datasetB[Date],B33) -> 1799 | E33: =C33+D33 -> 1985 | G33: 40568 | H33: 1336.9266 | N33: Historical period | O33: 01-Jan-2011 to 14-Feb-2011
B34: 40569 | C34: =SUMIFS(Cleaned_datasetB[Casual_Rentals],Cleaned_datasetB[Date],B34) -> 34 | D34: =SUMIFS(Cleaned_datasetB[Registered_Rentals],Cleaned_datasetB[Date],B34) -> 472 | E34: =C34+D34 -> 506 | G34: 40569 | H34: 1431.857 | N34: Forecast period | O34: 15-Feb-2011 to 07 March 2011
B35: 40570 | C35: =SUMIFS(Cleaned_datasetB[Casual_Rentals],Cleaned_datasetB[Date],B35) -> 15 | D35: =SUMIFS(Cleaned_datasetB[Registered_Rentals],Cleaned_datasetB[Date],B35) -> 416 | E35: =C35+D35 -> 431 | G35: 40570 | H35: 1539.5627 | N35: Average historical daily demand | O35: 1,295.64 rentals/day
B36: 40571 | C36: =SUMIFS(Cleaned_datasetB[Casual_Rentals],Cleaned_datasetB[Date],B36) -> 38 | D36: =SUMIFS(Cleaned_datasetB[Registered_Rentals],Cleaned_datasetB[Date],B36) -> 1129 | E36: =C36+D36 -> 1167 | G36: 40571 | H36: 1544.1805 | N36: Average forecast daily demand | O36: 1,500.49 rentals/day
B37: 40572 | C37: =SUMIFS(Cleaned_datasetB[Casual_Rentals],Cleaned_datasetB[Date],B37) -> 123 | D37: =SUMIFS(Cleaned_datasetB[Registered_Rentals],Cleaned_datasetB[Date],B37) -> 975 | E37: =C37+D37 -> 1098 | G37: 40572 | H37: 1149.7581 | N37: Forecast vs Historical Change | O37: =TEXT((1500.49-1295.64)/1295.64,"0.00%")&" increase" -> 15.81% increase
B38: 40573 | C38: =SUMIFS(Cleaned_datasetB[Casual_Rentals],Cleaned_datasetB[Date],B38) -> 140 | D38: =SUMIFS(Cleaned_datasetB[Registered_Rentals],Cleaned_datasetB[Date],B38) -> 956 | E38: =C38+D38 -> 1096 | G38: 40573 | H38: 1199.0402
B39: 40574 | C39: =SUMIFS(Cleaned_datasetB[Casual_Rentals],Cleaned_datasetB[Date],B39) -> 42 | D39: =SUMIFS(Cleaned_datasetB[Registered_Rentals],Cleaned_datasetB[Date],B39) -> 1459 | E39: =C39+D39 -> 1501 | G39: 40574 | H39: 1403.5657 | M39: Forecast average (1,500/day) is ~16% above historical average (1,296/day) — projects rising demand
B40: 40575 | C40: =SUMIFS(Cleaned_datasetB[Casual_Rentals],Cleaned_datasetB[Date],B40) -> 47 | D40: =SUMIFS(Cleaned_datasetB[Registered_Rentals],Cleaned_datasetB[Date],B40) -> 1313 | E40: =C40+D40 -> 1360 | G40: 40575 | H40: 1379.7139
B41: 40576 | C41: =SUMIFS(Cleaned_datasetB[Casual_Rentals],Cleaned_datasetB[Date],B41) -> 72 | D41: =SUMIFS(Cleaned_datasetB[Registered_Rentals],Cleaned_datasetB[Date],B41) -> 1454 | E41: =C41+D41 -> 1526 | G41: 40576 | H41: 1474.6444
B42: 40577 | C42: =SUMIFS(Cleaned_datasetB[Casual_Rentals],Cleaned_datasetB[Date],B42) -> 61 | D42: =SUMIFS(Cleaned_datasetB[Registered_Rentals],Cleaned_datasetB[Date],B42) -> 1489 | E42: =C42+D42 -> 1550 | G42: 40577 | H42: 1582.3501
B43: 40578 | C43: =SUMIFS(Cleaned_datasetB[Casual_Rentals],Cleaned_datasetB[Date],B43) -> 88 | D43: =SUMIFS(Cleaned_datasetB[Registered_Rentals],Cleaned_datasetB[Date],B43) -> 1620 | E43: =C43+D43 -> 1708 | G43: 40578 | H43: 1586.9679
B44: 40579 | C44: =SUMIFS(Cleaned_datasetB[Casual_Rentals],Cleaned_datasetB[Date],B44) -> 100 | D44: =SUMIFS(Cleaned_datasetB[Registered_Rentals],Cleaned_datasetB[Date],B44) -> 905 | E44: =C44+D44 -> 1005 | G44: 40579 | H44: 1192.5455
B45: 40580 | C45: =SUMIFS(Cleaned_datasetB[Casual_Rentals],Cleaned_datasetB[Date],B45) -> 354 | D45: =SUMIFS(Cleaned_datasetB[Registered_Rentals],Cleaned_datasetB[Date],B45) -> 1269 | E45: =C45+D45 -> 1623 | G45: 40580 | H45: 1241.8276
B46: 40581 | C46: =SUMIFS(Cleaned_datasetB[Casual_Rentals],Cleaned_datasetB[Date],B46) -> 120 | D46: =SUMIFS(Cleaned_datasetB[Registered_Rentals],Cleaned_datasetB[Date],B46) -> 1592 | E46: =C46+D46 -> 1712 | G46: 40581 | H46: 1446.3531
B47: 40582 | C47: =SUMIFS(Cleaned_datasetB[Casual_Rentals],Cleaned_datasetB[Date],B47) -> 64 | D47: =SUMIFS(Cleaned_datasetB[Registered_Rentals],Cleaned_datasetB[Date],B47) -> 1466 | E47: =C47+D47 -> 1530 | G47: 40582 | H47: 1422.5013
B48: 40583 | C48: =SUMIFS(Cleaned_datasetB[Casual_Rentals],Cleaned_datasetB[Date],B48) -> 53 | D48: =SUMIFS(Cleaned_datasetB[Registered_Rentals],Cleaned_datasetB[Date],B48) -> 1552 | E48: =C48+D48 -> 1605 | G48: 40583 | H48: 1517.4318
B49: 40584 | C49: =SUMIFS(Cleaned_datasetB[Casual_Rentals],Cleaned_datasetB[Date],B49) -> 47 | D49: =SUMIFS(Cleaned_datasetB[Registered_Rentals],Cleaned_datasetB[Date],B49) -> 1491 | E49: =C49+D49 -> 1538 | G49: 40584 | H49: 1625.1374
B50: 40585 | C50: =SUMIFS(Cleaned_datasetB[Casual_Rentals],Cleaned_datasetB[Date],B50) -> 149 | D50: =SUMIFS(Cleaned_datasetB[Registered_Rentals],Cleaned_datasetB[Date],B50) -> 1597 | E50: =C50+D50 -> 1746 | G50: 40585 | H50: 1629.7553
B51: 40586 | C51: =SUMIFS(Cleaned_datasetB[Casual_Rentals],Cleaned_datasetB[Date],B51) -> 288 | D51: =SUMIFS(Cleaned_datasetB[Registered_Rentals],Cleaned_datasetB[Date],B51) -> 1184 | E51: =C51+D51 -> 1472 | G51: 40586 | H51: 1235.3329
... B53: 40588 | C53: =SUMIFS(Cleaned_datasetB[Casual_Rentals],Cleaned_datasetB[Date],B53) -> 8 | D53: =SUMIFS(Cleaned_datasetB[Registered_Rentals],Cleaned_datasetB[Date],B53) -> 143 | E53: =C53+D53 -> 151 | G53: 40588 | H53: 1489.1405
...

Sheet Anomaly
C2: ANOMALY ANALYSIS — BIKE SHARING DEMAND
B6: DAILY DEMAND STATISTICAL SUMMARY | F6: ANOMALY THRESHOLDS | J6: ANOMALY TABLE
B8: Metric | C8: Value | J8: Date | K8: Casual | L8: Registered | M8: Total Rentals | N8: Status | O8: Context
B9: Number of Days | C9: =COUNT(Forecast!E9:E53) -> 45 | F9: Metric | G9: Formula | J9: =Forecast!B9 -> 40544 | K9: =Forecast!C9 -> 331 | L9: =Forecast!D9 -> 654 | M9: =Forecast!E9 -> 985 | N9: =IF(M9<$G$13,"Low Anomaly",IF(M9>$G$14,"High Anomaly","Normal")) -> Normal | O9: =IF(N9="Normal","","Hourly records: "&COUNTIFS(Cleaned_datasetB[Date],">="&J9,Cleaned_datasetB[Date],"<"&(J9+1)))
B10: Average Daily Rentals | C10: =AVERAGE(Forecast!E9:E53) -> 1295.6444 | F10: Q1 | G10: =_xlfn.QUARTILE.INC(Forecast!E9:E53,1) -> 1005 | J10: =Forecast!B10 -> 40545 | K10: =Forecast!C10 -> 131 | L10: =Forecast!D10 -> 670 | M10: =Forecast!E10 -> 801 | N10: =IF(M10<$G$13,"Low Anomaly",IF(M10>$G$14,"High Anomaly","Normal")) -> Normal | O10: =IF(N10="Normal","","Hourly records: "&COUNTIFS(Cleaned_datasetB[Date],">="&J10,Cleaned_datasetB[Date],"<"&(J10+1)))
B11: Median Daily Rentals | C11: =MEDIAN(Forecast!E9:E53) -> 1406 | F11: Q3 | G11: =_xlfn.QUARTILE.INC(Forecast!E9:E53,3) -> 1562 | J11: =Forecast!B11 -> 40546 | K11: =Forecast!C11 -> 120 | L11: =Forecast!D11 -> 1229 | M11: =Forecast!E11 -> 1349 | N11: =IF(M11<$G$13,"Low Anomaly",IF(M11>$G$14,"High Anomaly","Normal")) -> Normal | O11: =IF(N11="Normal","","Hourly records: "&COUNTIFS(Cleaned_datasetB[Date],">="&J11,Cleaned_datasetB[Date],"<"&(J11+1)))
B12: Q1 | C12: =_xlfn.QUARTILE.INC(Forecast!E9:E53,1) -> 1005 | F12: IQR | G12: =C13-C12 -> 557 | J12: =Forecast!B12 -> 40547 | K12: =Forecast!C12 -> 108 | L12: =Forecast!D12 -> 1454 | M12: =Forecast!E12 -> 1562 | N12: =IF(M12<$G$13,"Low Anomaly",IF(M12>$G$14,"High Anomaly","Normal")) -> Normal | O12: =IF(N12="Normal","","Hourly records: "&COUNTIFS(Cleaned_datasetB[Date],">="&J12,Cleaned_datasetB[Date],"<"&(J12+1)))
B13: Q3 | C13: =_xlfn.QUARTILE.INC(Forecast!E9:E53,3) -> 1562 | F13: Lower Threshold | G13: =G10-(1.5*G12) -> 169.5 | J13: =Forecast!B13 -> 40548 | K13: =Forecast!C13 -> 82 | L13: =Forecast!D13 -> 1518 | M13: =Forecast!E13 -> 1600 | N13: =IF(M13<$G$13,"Low Anomaly",IF(M13>$G$14,"High Anomaly","Normal")) -> Normal | O13: =IF(N13="Normal","","Hourly records: "&COUNTIFS(Cleaned_datasetB[Date],">="&J13,Cleaned_datasetB[Date],"<"&(J13+1)))
B14: IQR | C14: =C13-C12 -> 557 | F14: Upper Threshold | G14: =G11+(1.5*G12) -> 2397.5 | J14: =Forecast!B14 -> 40549 | K14: =Forecast!C14 -> 88 | L14: =Forecast!D14 -> 1518 | M14: =Forecast!E14 -> 1606 | N14: =IF(M14<$G$13,"Low Anomaly",IF(M14>$G$14,"High Anomaly","Normal")) -> Normal | O14: =IF(N14="Normal","","Hourly records: "&COUNTIFS(Cleaned_datasetB[Date],">="&J14,Cleaned_datasetB[Date],"<"&(J14+1)))
B15: Minimum Daily Rentals | C15: =MIN(Forecast!E9:E53) -> 151 | J15: =Forecast!B15 -> 40550 | K15: =Forecast!C15 -> 148 | L15: =Forecast!D15 -> 1362 | M15: =Forecast!E15 -> 1510 | N15: =IF(M15<$G$13,"Low Anomaly",IF(M15>$G$14,"High Anomaly","Normal")) -> Normal | O15: =IF(N15="Normal","","Hourly records: "&COUNTIFS(Cleaned_datasetB[Date],">="&J15,Cleaned_datasetB[Date],"<"&(J15+1)))
B16: Maximum Daily Rentals | C16: =MAX(Forecast!E9:E53) -> 1985 | J16: =Forecast!B16 -> 40551 | K16: =Forecast!C16 -> 68 | L16: =Forecast!D16 -> 891 | M16: =Forecast!E16 -> 959 | N16: =IF(M16<$G$13,"Low Anomaly",IF(M16>$G$14,"High Anomaly","Normal")) -> Normal | O16: =IF(N16="Normal","","Hourly records: "&COUNTIFS(Cleaned_datasetB[Date],">="&J16,Cleaned_datasetB[Date],"<"&(J16+1)))
J17: =Forecast!B17 -> 40552 | K17: =Forecast!C17 -> 54 | L17: =Forecast!D17 -> 768 | M17: =Forecast!E17 -> 822 | N17: =IF(M17<$G$13,"Low Anomaly",IF(M17>$G$14,"High Anomaly","Normal")) -> Normal | O17: =IF(N17="Normal","","Hourly records: "&COUNTIFS(Cleaned_datasetB[Date],">="&J17,Cleaned_datasetB[Date],"<"&(J17+1)))
B18: D. ANOMALY CHART | J18: =Forecast!B18 -> 40553 | K18: =Forecast!C18 -> 41 | L18: =Forecast!D18 -> 1280 | M18: =Forecast!E18 -> 1321 | N18: =IF(M18<$G$13,"Low Anomaly",IF(M18>$G$14,"High Anomaly","Normal")) -> Normal | O18: =IF(N18="Normal","","Hourly records: "&COUNTIFS(Cleaned_datasetB[Date],">="&J18,Cleaned_datasetB[Date],"<"&(J18+1)))
J19: =Forecast!B19 -> 40554 | K19: =Forecast!C19 -> 43 | L19: =Forecast!D19 -> 1220 | M19: =Forecast!E19 -> 1263 | N19: =IF(M19<$G$13,"Low Anomaly",IF(M19>$G$14,"High Anomaly","Normal")) -> Normal | O19: =IF(N19="Normal","","Hourly records: "&COUNTIFS(Cleaned_datasetB[Date],">="&J19,Cleaned_datasetB[Date],"<"&(J19+1)))
J20: =Forecast!B20 -> 40555 | K20: =Forecast!C20 -> 25 | L20: =Forecast!D20 -> 1137 | M20: =Forecast!E20 -> 1162 | N20: =IF(M20<$G$13,"Low Anomaly",IF(M20>$G$14,"High Anomaly","Normal")) -> Normal | O20: =IF(N20="Normal","","Hourly records: "&COUNTIFS(Cleaned_datasetB[Date],">="&J20,Cleaned_datasetB[Date],"<"&(J20+1)))
J21: =Forecast!B21 -> 40556 | K21: =Forecast!C21 -> 38 | L21: =Forecast!D21 -> 1368 | M21: =Forecast!E21 -> 1406 | N21: =IF(M21<$G$13,"Low Anomaly",IF(M21>$G$14,"High Anomaly","Normal")) -> Normal | O21: =IF(N21="Normal","","Hourly records: "&COUNTIFS(Cleaned_datasetB[Date],">="&J21,Cleaned_datasetB[Date],"<"&(J21+1)))
J22: =Forecast!B22 -> 40557 | K22: =Forecast!C22 -> 54 | L22: =Forecast!D22 -> 1367 | M22: =Forecast!E22 -> 1421 | N22: =IF(M22<$G$13,"Low Anomaly",IF(M22>$G$14,"High Anomaly","Normal")) -> Normal | O22: =IF(N22="Normal","","Hourly records: "&COUNTIFS(Cleaned_datasetB[Date],">="&J22,Cleaned_datasetB[Date],"<"&(J22+1)))
J23: =Forecast!B23 -> 40558 | K23: =Forecast!C23 -> 222 | L23: =Forecast!D23 -> 1026 | M23: =Forecast!E23 -> 1248 | N23: =IF(M23<$G$13,"Low Anomaly",IF(M23>$G$14,"High Anomaly","Normal")) -> Normal | O23: =IF(N23="Normal","","Hourly records: "&COUNTIFS(Cleaned_datasetB[Date],">="&J23,Cleaned_datasetB[Date],"<"&(J23+1)))
J24: =Forecast!B24 -> 40559 | K24: =Forecast!C24 -> 251 | L24: =Forecast!D24 -> 953 | M24: =Forecast!E24 -> 1204 | N24: =IF(M24<$G$13,"Low Anomaly",IF(M24>$G$14,"High Anomaly","Normal")) -> Normal | O24: =IF(N24="Normal","","Hourly records: "&COUNTIFS(Cleaned_datasetB[Date],">="&J24,Cleaned_datasetB[Date],"<"&(J24+1)))
J25: =Forecast!B25 -> 40560 | K25: =Forecast!C25 -> 117 | L25: =Forecast!D25 -> 883 | M25: =Forecast!E25 -> 1000 | N25: =IF(M25<$G$13,"Low Anomaly",IF(M25>$G$14,"High Anomaly","Normal")) -> Normal | O25: =IF(N25="Normal","","Hourly records: "&COUNTIFS(Cleaned_datasetB[Date],">="&J25,Cleaned_datasetB[Date],"<"&(J25+1)))
J26: =Forecast!B26 -> 40561 | K26: =Forecast!C26 -> 9 | L26: =Forecast!D26 -> 674 | M26: =Forecast!E26 -> 683 | N26: =IF(M26<$G$13,"Low Anomaly",IF(M26>$G$14,"High Anomaly","Normal")) -> Normal | O26: =IF(N26="Normal","","Hourly records: "&COUNTIFS(Cleaned_datasetB[Date],">="&J26,Cleaned_datasetB[Date],"<"&(J26+1)))
J27: =Forecast!B27 -> 40562 | K27: =Forecast!C27 -> 78 | L27: =Forecast!D27 -> 1572 | M27: =Forecast!E27 -> 1650 | N27: =IF(M27<$G$13,"Low Anomaly",IF(M27>$G$14,"High Anomaly","Normal")) -> Normal | O27: =IF(N27="Normal","","Hourly records: "&COUNTIFS(Cleaned_datasetB[Date],">="&J27,Cleaned_datasetB[Date],"<"&(J27+1)))
J28: =Forecast!B28 -> 40563 | K28: =Forecast!C28 -> 83 | L28: =Forecast!D28 -> 1844 | M28: =Forecast!E28 -> 1927 | N28: =IF(M28<$G$13,"Low Anomaly",IF(M28>$G$14,"High Anomaly","Normal")) -> Normal | O28: =IF(N28="Normal","","Hourly records: "&COUNTIFS(Cleaned_datasetB[Date],">="&J28,Cleaned_datasetB[Date],"<"&(J28+1)))
J29: =Forecast!B29 -> 40564 | K29: =Forecast!C29 -> 75 | L29: =Forecast!D29 -> 1468 | M29: =Forecast!E29 -> 1543 | N29: =IF(M29<$G$13,"Low Anomaly",IF(M29>$G$14,"High Anomaly","Normal")) -> Normal | O29: =IF(N29="Normal","","Hourly records: "&COUNTIFS(Cleaned_datasetB[Date],">="&J29,Cleaned_datasetB[Date],"<"&(J29+1)))
J30: =Forecast!B30 -> 40565 | K30: =Forecast!C30 -> 93 | L30: =Forecast!D30 -> 888 | M30: =Forecast!E30 -> 981 | N30: =IF(M30<$G$13,"Low Anomaly",IF(M30>$G$14,"High Anomaly","Normal")) -> Normal | O30: =IF(N30="Normal","","Hourly records: "&COUNTIFS(Cleaned_datasetB[Date],">="&J30,Cleaned_datasetB[Date],"<"&(J30+1)))
... J33: =Forecast!B33 -> 40568 | K33: =Forecast!C33 -> 186 | L33: =Forecast!D33 -> 1799 | M33: =Forecast!E33 -> 1985 | N33: =IF(M33<$G$13,"Low Anomaly",IF(M33>$G$14,"High Anomaly","Normal")) -> Normal | O33: =IF(N33="Normal","","Hourly records: "&COUNTIFS(Cleaned_datasetB[Date],">="&J33,Cleaned_datasetB[Date],"<"&(J33+1)))
B34: ANOMALY SUMMARY | J34: =Forecast!B34 -> 40569 | K34: =Forecast!C34 -> 34 | L34: =Forecast!D34 -> 472 | M34: =Forecast!E34 -> 506 | N34: =IF(M34<$G$13,"Low Anomaly",IF(M34>$G$14,"High Anomaly","Normal")) -> Normal | O34: =IF(N34="Normal","","Hourly records: "&COUNTIFS(Cleaned_datasetB[Date],">="&J34,Cleaned_datasetB[Date],"<"&(J34+1)))
J35: =Forecast!B35 -> 40570 | K35: =Forecast!C35 -> 15 | L35: =Forecast!D35 -> 416 | M35: =Forecast!E35 -> 431 | N35: =IF(M35<$G$13,"Low Anomaly",IF(M35>$G$14,"High Anomaly","Normal")) -> Normal | O35: =IF(N35="Normal","","Hourly records: "&COUNTIFS(Cleaned_datasetB[Date],">="&J35,Cleaned_datasetB[Date],"<"&(J35+1)))
C36: Metric | D36: Value | J36: =Forecast!B36 -> 40571 | K36: =Forecast!C36 -> 38 | L36: =Forecast!D36 -> 1129 | M36: =Forecast!E36 -> 1167 | N36: =IF(M36<$G$13,"Low Anomaly",IF(M36>$G$14,"High Anomaly","Normal")) -> Normal | O36: =IF(N36="Normal","","Hourly records: "&COUNTIFS(Cleaned_datasetB[Date],">="&J36,Cleaned_datasetB[Date],"<"&(J36+1)))
C37: Total Days Analyzed | D37: =COUNT(J9:J53) -> 45 | J37: =Forecast!B37 -> 40572 | K37: =Forecast!C37 -> 123 | L37: =Forecast!D37 -> 975 | M37: =Forecast!E37 -> 1098 | N37: =IF(M37<$G$13,"Low Anomaly",IF(M37>$G$14,"High Anomaly","Normal")) -> Normal | O37: =IF(N37="Normal","","Hourly records: "&COUNTIFS(Cleaned_datasetB[Date],">="&J37,Cleaned_datasetB[Date],"<"&(J37+1)))
C38: High Anomalies | D38: =COUNTIF(N9:N53,"High Anomaly") -> 0 | J38: =Forecast!B38 -> 40573 | K38: =Forecast!C38 -> 140 | L38: =Forecast!D38 -> 956 | M38: =Forecast!E38 -> 1096 | N38: =IF(M38<$G$13,"Low Anomaly",IF(M38>$G$14,"High Anomaly","Normal")) -> Normal | O38: =IF(N38="Normal","","Hourly records: "&COUNTIFS(Cleaned_datasetB[Date],">="&J38,Cleaned_datasetB[Date],"<"&(J38+1)))
